Workbook

Sheet China Index ROIC
A1: 证券简称 | B1: 证券代码 | C1: ROIC中位数 | D1: ROIC方差 | E1: 行业
A2: 重庆啤酒 | B2: 600132 | C2: 20.64 | D2: 138.1721 | E2: 食品饮料-饮料制造-啤酒
A3: 山西汾酒 | B3: 600809 | C3: 9.62 | D3: 36.2959 | E3: 食品饮料-白酒-白酒Ⅲ
A4: 明德生物 | B4: 002932 | C4: 9.62 | D4: 142.5766 | E4: 医药生物-医疗器械-体外诊断
A5: 万泰生物 | B5: 603392 | C5: 9.16 | D5: 48.5245 | E5: 医药生物-生物制品-疫苗
A6: 迈瑞医疗 | B6: 300760 | C6: 9.04 | D6: 4.9761 | E6: 医药生物-医疗器械-医疗设备
A7: 金域医学 | B7: 603882 | C7: 8.32 | D7: 24.4794 | E7: 医药生物-医疗服务-其他医疗服务
A8: 达安基因 | B8: 002030 | C8: 8.14 | D8: 80.2728 | E8: 医药生物-医疗器械-体外诊断
A9: 水井坊 | B9: 600779 | C9: 7.8 | D9: 85.2078 | E9: 食品饮料-白酒-白酒Ⅲ
A10: 东方生物 | B10: 688298 | C10: 7.76 | D10: 350.706 | E10: 医药生物-医疗器械-体外诊断
A11: 智飞生物 | B11: 300122 | C11: 7.66 | D11: 38.8521 | E11: 医药生物-生物制品-疫苗
A12: 大全能源 | B12: 688303 | C12: 7.62 | D12: 54.3253 | E12: 电力设备-光伏设备-硅料硅片
A13: 贵州茅台 | B13: 600519 | C13: 7.6 | D13: 1.3797 | E13: 食品饮料-白酒-白酒Ⅲ
... A4082: 神州细胞 | B4082: 688520 | C4082: -15.83 | D4082: 172.8739 | E4082: 医药生物-生物制品-其他生物制品

Sheet MSCI中国成分股
A1: 股票代码 | B1: 股票简称
A2: 688303 | B2: 大全能源
A3: 002939 | B3: 长城证券
A4: 601118 | B4: 海南橡胶
A5: 601000 | B5: 唐山港
A6: 600066 | B6: 宇通客车
A7: 002459 | B7: 晶澳科技
A8: 603259 | B8: 药明康德
A9: 601838 | B9: 成都银行
A10: 600000 | B10: 浦发银行
A11: 002463 | B11: 沪电股份
A12: 601766 | B12: 中国中车
... A560: 688235 | B560: 百济神州-U

Sheet 过滤
A1: 证券简称 | B1: 证券代码 | C1: ROIC中位数 | D1: ROIC方差 | E1: 行业 | F1: 是否MSCI
A2: 重庆啤酒 | B2: 600132 | C2: 20.64 | D2: 138.1721 | E2: 食品饮料-饮料制造-啤酒 | F2: =VLOOKUP(B2,MSCI中国成分股!A:B,1,) -> 600132
A3: 山西汾酒 | B3: 600809 | C3: 9.62 | D3: 36.2959 | E3: 食品饮料-白酒-白酒Ⅲ | F3: =VLOOKUP(B3,MSCI中国成分股!A:B,1,) -> 600809
A4: 万泰生物 | B4: 603392 | C4: 9.16 | D4: 48.5245 | E4: 医药生物-生物制品-疫苗 | F4: =VLOOKUP(B4,MSCI中国成分股!A:B,1,) -> 603392
A5: 迈瑞医疗 | B5: 300760 | C5: 9.04 | D5: 4.9761 | E5: 医药生物-医疗器械-医疗设备 | F5: =VLOOKUP(B5,MSCI中国成分股!A:B,1,) -> 300760
A6: 水井坊 | B6: 600779 | C6: 7.8 | D6: 85.2078 | E6: 食品饮料-白酒-白酒Ⅲ | F6: =VLOOKUP(B6,MSCI中国成分股!A:B,1,) -> 600779
A7: 智飞生物 | B7: 300122 | C7: 7.66 | D7: 38.8521 | E7: 医药生物-生物制品-疫苗 | F7: =VLOOKUP(B7,MSCI中国成分股!A:B,1,) -> 300122
A8: 大全能源 | B8: 688303 | C8: 7.62 | D8: 54.3253 | E8: 电力设备-光伏设备-硅料硅片 | F8: =VLOOKUP(B8,MSCI中国成分股!A:B,1,) -> 688303
A9: 中国电信 | B9: 601728 | C9: 1.39 | D9: 0.4669 | E9: 通信-通信服务-电信运营商 | F9: =VLOOKUP(B9,MSCI中国成分股!A:B,1,) -> #N/A
A10: 贵州茅台 | B10: 600519 | C10: 7.6 | D10: 1.3797 | E10: 食品饮料-白酒-白酒Ⅲ | F10: =VLOOKUP(B10,MSCI中国成分股!A:B,1,) -> 600519
A11: 健帆生物 | B11: 300529 | C11: 7.43 | D11: 10.219 | E11: 医药生物-医疗器械-医疗耗材 | F11: =VLOOKUP(B11,MSCI中国成分股!A:B,1,) -> 300529
A12: 亿联网络 | B12: 300628 | C12: 7.29 | D12: 1.8425 | E12: 通信-通信设备-通信终端及配件 | F12: =VLOOKUP(B12,MSCI中国成分股!A:B,1,) -> 300628
A13: 伟星新材 | B13: 002372 | C13: 7.28 | D13: 9.3327 | E13: 建筑材料-建筑材料-管材 | F13: =VLOOKUP(B13,MSCI中国成分股!A:B,1,) -> 002372
... A4082: 美之高 | B4082: 834765 | C4082: 1.91 | D4082: 6.6158 | E4082: 轻工制造-家居用品-成品家居 | F4082: =VLOOKUP(B4082,MSCI中国成分股!A:B,1,) -> #N/A

Sheet 当前走势
A1: 股票代码 | B1: 股票代码 | C1: 股票简称 | D1: 现价(元) | E1: 涨跌幅(%) | F1: a股流通市值 (元)2024.09.18
A2: 600519.SH | B2: =LEFT(A2,6) -> 600519 | C2: 贵州茅台 | D2: 1266.9 | E2: -2.86 | F2: 1591477000000
A3: 601398.SH | B3: =LEFT(A3,6) -> 601398 | C3: 工商银行 | D3: 5.68 | E3: 2.16 | F3: 1531397400000
A4: 601288.SH | B4: =LEFT(A4,6) -> 601288 | C4: 农业银行 | D4: 4.5 | E4: 1.35 | F4: 1436598900000
A5: 601857.SH | B5: =LEFT(A5,6) -> 601857 | C5: 中国石油 | D5: 8.06 | E5: 2.03 | F5: 1305091950000
A6: 601988.SH | B6: =LEFT(A6,6) -> 601988 | C6: 中国银行 | D6: 4.65 | E6: 1.53 | F6: 980059640000
A7: 601628.SH | B7: =LEFT(A7,6) -> 601628 | C7: 中国人寿 | D7: 35.12 | E7: 3.05 | F7: 731322370000
A8: 300750.SZ | B8: =LEFT(A8,6) -> 300750 | C8: 宁德时代 | D8: 186.4 | E8: 1.58 | F8: 726000880000
A9: 600900.SH | B9: =LEFT(A9,6) -> 600900 | C9: 长江电力 | D9: 28.32 | E9: 0.07 | F9: 679885500000
A10: 600036.SH | B10: =LEFT(A10,6) -> 600036 | C10: 招商银行 | D10: 31.11 | E10: 1.67 | F10: 641766460000
A11: 601088.SH | B11: =LEFT(A11,6) -> 601088 | C11: 中国神华 | D11: 38.24 | E11: 1.03 | F11: 630617290000
A12: 600028.SH | B12: =LEFT(A12,6) -> 600028 | C12: 中国石化 | D12: 6.39 | E12: 3.23 | F12: 606870890000
A13: 601318.SH | B13: =LEFT(A13,6) -> 601318 | C13: 中国平安 | D13: 43.7 | E13: 1.89 | F13: 470328140000
... A46: 002371.SZ | B46: =LEFT(A46,6) -> 002371 | C46: 北方华创 | D46: 294.68 | E46: 0.57 | F46: 156849060000
A47: 600150.SH | B47: =LEFT(A47,6) -> 600150 | C47: 中国船舶 | D47: 34.9 | E47: -- | F47: 156087760000
A48: 003816.SZ | B48: =LEFT(A48,6) -> 003816 | C48: 中国广核 | D48: 3.96 | E48: 0.25 | F48: 155766540000
A49: 601633.SH | B49: =LEFT(A49,6) -> 601633 | C49: 长城汽车 | D49: 23.88 | E49: 3.24 | F49: 147520570000
A50: 000568.SZ | B50: =LEFT(A50,6) -> 000568 | C50: 泸州老窖 | D50: 100.02 | E50: -0.79 | F50: 146743430000
A51: 601818.SH | B51: =LEFT(A51,6) -> 601818 | C51: 光大银行 | D51: 3.05 | E51: 0.33 | F51: 141540790000
A52: 300059.SZ | B52: =LEFT(A52,6) -> 300059 | C52: 东方财富 | D52: 10.43 | E52: 0.48 | F52: 139337280000
A53: 600050.SH | B53: =LEFT(A53,6) -> 600050 | C53: 中国联通 | D53: 4.48 | E53: 0.22 | F53: 138726120000
A54: 600919.SH | B54: =LEFT(A54,6) -> 600919 | C54: 江苏银行 | D54: 7.53 | E54: 0.53 | F54: 138185470000
A55: 002714.SZ | B55: =LEFT(A55,6) -> 002714 | C55: 牧原股份 | D55: 36.16 | E55: -3.34 | F55: 137795530000
A56: 600104.SH | B56: =LEFT(A56,6) -> 600104 | C56: 上汽集团 | D56: 11.78 | E56: 1.99 | F56: 136357030000
A57: 600887.SH | B57: =LEFT(A57,6) -> 600887 | C57: 伊利股份 | D57: 21.37 | E57: -0.93 | F57: 134739860000
A58: 600031.SH | B58: =LEFT(A58,6) -> 600031 | C58: 三一重工 | D58: 15.84 | E58: 3.67 | F58: 134073179000
A59: 000725.SZ | B59: =LEFT(A59,6) -> 000725 | C59: 京东方A | D59: 3.63 | E59: -0.55 | F59: 133775322000
... A71: 601127.SH | B71: =LEFT(A71,6) -> 601127 | C71: 赛力斯 | D71: 75.32 | E71: 2.14 | F71: 113716795000
A72: 601989.SH | B72: =LEFT(A72,6) -> 601989 | C72: 中国重工 | D72: 4.98 | E72: -- | F72: 113554136000
A73: 600999.SH | B73: =LEFT(A73,6) -> 600999 | C73: 招商证券 | D73: 15.03 | E73: 0.33 | F73: 111552739000
A74: 600760.SH | B74: =LEFT(A74,6) -> 600760 | C74: 中航沈飞 | D74: 40.15 | E74: -0.82 | F74: 110201183000
A75: 601211.SH | B75: =LEFT(A75,6) -> 601211 | C75: 国泰君安 | D75: 14.7 | E75: -- | F75: 109960746000
A76: 601006.SH | B76: =LEFT(A76,6) -> 601006 | C76: 大秦铁路 | D76: 5.99 | E76: 1.18 | F76: 109360909000
A77: 002304.SZ | B77: =LEFT(A77,6) -> 002304 | C77: 洋河股份 | D77: 72.16 | E77: -1.03 | F77: 108435320000
A78: 600886.SH | B78: =LEFT(A78,6) -> 600886 | C78: 国投电力 | D78: 15.44 | E78: 0.2 | F78: 107553084000
A79: 600989.SH | B79: =LEFT(A79,6) -> 600989 | C79: 宝丰能源 | D79: 14.63 | E79: 1.25 | F79: 107287057000
A80: 601888.SH | B80: =LEFT(A80,6) -> 601888 | C80: 中国中免 | D80: 53.76 | E80: -1.97 | F80: 104965085000
A81: 601169.SH | B81: =LEFT(A81,6) -> 601169 | C81: 北京银行 | D81: 4.91 | E81: 0.2 | F81: 103812053000
A82: 600660.SH | B82: =LEFT(A82,6) -> 600660 | C82: 福耀玻璃 | D82: 51.75 | E82: 4.34 | F82: 103654543000
A83: 603501.SH | B83: =LEFT(A83,6) -> 603501 | C83: 韦尔股份 | D83: 84.97 | E83: 0.71 | F83: 103189863000
...

Sheet MSCI最终筛选标的-原
A1: 证券简称 | B1: 证券代码 | C1: 价格[0918] | D1: 流通市值[0918] | E1: ROIC中位数 | F1: ROIC方差 | G1: 行业 | H1: 分类 | I1: 走势详情
A2: 山金国际 | B2: 000975 | C2: =VLOOKUP(B2,当前走势!$B:$F,3,) -> 16.18 | D2: =VLOOKUP(B2,当前走势!$B:$F,5,FALSE)/100000000 -> 402.41137 | E2: =VLOOKUP(B2,'China Index ROIC'!$B:$D,2,FALSE) -> 2.83 | F2: =VLOOKUP(B2,'China Index ROIC'!$B:$D,3,FALSE) -> 0.3927 | G2: =VLOOKUP(B2,'China Index ROIC'!B:E,4,FALSE) -> 有色金属-贵金属-贵金属Ⅲ | H2: 原材料 | I2: =CONCATENATE("https://gushitong.baidu.com/stock/ab-", B2) -> https://gushitong.baidu.com/stock/ab-000975
A3: 紫金矿业 | B3: 601899 | C3: =VLOOKUP(B3,当前走势!B:F,3,) -> 15.04 | D3: =VLOOKUP(B3,当前走势!$B:$F,5,FALSE)/100000000 -> 3091.6665 | E3: =VLOOKUP(B3,'China Index ROIC'!$B:$D,2,FALSE) -> 2.09 | F3: =VLOOKUP(B3,'China Index ROIC'!$B:$D,3,FALSE) -> 0.5921 | G3: =VLOOKUP(B3,'China Index ROIC'!B:E,4,FALSE) -> 有色金属-工业金属-铜 | H3: 原材料 | I3: =CONCATENATE("https://gushitong.baidu.com/stock/ab-", B3) -> https://gushitong.baidu.com/stock/ab-601899
A4: 片仔癀 | B4: 600436 | C4: =VLOOKUP(B4,当前走势!B:F,3,) -> 193.5 | D4: =VLOOKUP(B4,当前走势!$B:$F,5,FALSE)/100000000 -> 1167.4188 | E4: =VLOOKUP(B4,'China Index ROIC'!$B:$D,2,FALSE) -> 5.86 | F4: =VLOOKUP(B4,'China Index ROIC'!$B:$D,3,FALSE) -> 2.0427 | G4: =VLOOKUP(B4,'China Index ROIC'!B:E,4,FALSE) -> 医药生物-中药-中药Ⅲ | H4: 医疗 | I4: =CONCATENATE("https://gushitong.baidu.com/stock/ab-", B4) -> https://gushitong.baidu.com/stock/ab-600436
A5: 济川药业 | B5: 600566 | C5: =VLOOKUP(B5,当前走势!B:F,3,) -> 24.46 | D5: =VLOOKUP(B5,当前走势!$B:$F,5,FALSE)/100000000 -> 223.992 | E5: =VLOOKUP(B5,'China Index ROIC'!$B:$D,2,FALSE) -> 4.86 | F5: =VLOOKUP(B5,'China Index ROIC'!$B:$D,3,FALSE) -> 0.855 | G5: =VLOOKUP(B5,'China Index ROIC'!B:E,4,FALSE) -> 医药生物-中药-中药Ⅲ | H5: 医疗 | I5: =CONCATENATE("https://gushitong.baidu.com/stock/ab-", B5) -> https://gushitong.baidu.com/stock/ab-600566
A6: 华润三九 | B6: 000999 | C6: =VLOOKUP(B6,当前走势!B:F,3,) -> 37.37 | D6: =VLOOKUP(B6,当前走势!$B:$F,5,FALSE)/100000000 -> 476.72954 | E6: =VLOOKUP(B6,'China Index ROIC'!$B:$D,2,FALSE) -> 3.63 | F6: =VLOOKUP(B6,'China Index ROIC'!$B:$D,3,FALSE) -> 2.2219 | G6: =VLOOKUP(B6,'China Index ROIC'!B:E,4,FALSE) -> 医药生物-中药-中药Ⅲ | H6: 医疗 | I6: =CONCATENATE("https://gushitong.baidu.com/stock/ab-", B6) -> https://gushitong.baidu.com/stock/ab-000999
A7: 达仁堂 | B7: 600329 | C7: =VLOOKUP(B7,当前走势!B:F,3,) -> 26.75 | D7: =VLOOKUP(B7,当前走势!$B:$F,5,FALSE)/100000000 -> 151.36971 | E7: =VLOOKUP(B7,'China Index ROIC'!$B:$D,2,FALSE) -> 3.2 | F7: =VLOOKUP(B7,'China Index ROIC'!$B:$D,3,FALSE) -> 1.1317 | G7: =VLOOKUP(B7,'China Index ROIC'!B:E,4,FALSE) -> 医药生物-中药-中药Ⅲ | H7: 医疗 | I7: =CONCATENATE("https://gushitong.baidu.com/stock/ab-", B7) -> https://gushitong.baidu.com/stock/ab-600329
A8: 云南白药 | B8: 000538 | C8: =VLOOKUP(B8,当前走势!B:F,3,) -> 50.46 | D8: =VLOOKUP(B8,当前走势!$B:$F,5,FALSE)/100000000 -> 892.83926 | E8: =VLOOKUP(B8,'China Index ROIC'!$B:$D,2,FALSE) -> 2.58 | F8: =VLOOKUP(B8,'China Index ROIC'!$B:$D,3,FALSE) -> 1.2203 | G8: =VLOOKUP(B8,'China Index ROIC'!B:E,4,FALSE) -> 医药生物-中药-中药Ⅲ | H8: 医疗 | I8: =CONCATENATE("https://gushitong.baidu.com/stock/ab-", B8) -> https://gushitong.baidu.com/stock/ab-000538
A9: 同仁堂 | B9: 600085 | C9: =VLOOKUP(B9,当前走势!B:F,3,) -> 31.21 | D9: =VLOOKUP(B9,当前走势!$B:$F,5,FALSE)/100000000 -> 428.03587 | E9: =VLOOKUP(B9,'China Index ROIC'!$B:$D,2,FALSE) -> 2.25 | F9: =VLOOKUP(B9,'China Index ROIC'!$B:$D,3,FALSE) -> 0.2757 | G9: =VLOOKUP(B9,'China Index ROIC'!B:E,4,FALSE) -> 医药生物-中药-中药Ⅲ | H9: 医疗 | I9: =CONCATENATE("https://gushitong.baidu.com/stock/ab-", B9) -> https://gushitong.baidu.com/stock/ab-600085
A10: 白云山 | B10: 600332 | C10: =VLOOKUP(B10,当前走势!B:F,3,) -> 24.69 | D10: =VLOOKUP(B10,当前走势!$B:$F,5,FALSE)/100000000 -> 347.11448 | E10: =VLOOKUP(B10,'China Index ROIC'!$B:$D,2,FALSE) -> 2.05 | F10: =VLOOKUP(B10,'China Index ROIC'!$B:$D,3,FALSE) -> 1.7235 | G10: =VLOOKUP(B10,'China Index ROIC'!B:E,4,FALSE) -> 医药生物-中药-中药Ⅲ | H10: 医疗 | I10: =CONCATENATE("https://gushitong.baidu.com/stock/ab-", B10) -> https://gushitong.baidu.com/stock/ab-600332
A11: 国药股份 | B11: 600511 | C11: =VLOOKUP(B11,当前走势!B:F,3,) -> 27.4 | D11: =VLOOKUP(B11,当前走势!$B:$F,5,FALSE)/100000000 -> 151.61692 | E11: =VLOOKUP(B11,'China Index ROIC'!$B:$D,2,FALSE) -> 3.33 | F11: =VLOOKUP(B11,'China Index ROIC'!$B:$D,3,FALSE) -> 0.4803 | G11: =VLOOKUP(B11,'China Index ROIC'!B:E,4,FALSE) -> 医药生物-医药商业-医药流通 | H11: 医疗 | I11: =CONCATENATE("https://gushitong.baidu.com/stock/ab-", B11) -> https://gushitong.baidu.com/stock/ab-600511
A12: 益丰药房 | B12: 603939 | C12: =VLOOKUP(B12,当前走势!B:F,3,) -> 17.85 | D12: =VLOOKUP(B12,当前走势!$B:$F,5,FALSE)/100000000 -> 215.93847 | E12: =VLOOKUP(B12,'China Index ROIC'!$B:$D,2,FALSE) -> 2.63 | F12: =VLOOKUP(B12,'China Index ROIC'!$B:$D,3,FALSE) -> 0.2376 | G12: =VLOOKUP(B12,'China Index ROIC'!B:E,4,FALSE) -> 医药生物-医药商业-药店 | H12: 医疗 | I12: =CONCATENATE("https://gushitong.baidu.com/stock/ab-", B12) -> https://gushitong.baidu.com/stock/ab-603939
A13: 新产业 | B13: 300832 | C13: =VLOOKUP(B13,当前走势!B:F,3,) -> 69.86 | D13: =VLOOKUP(B13,当前走势!$B:$F,5,FALSE)/100000000 -> 475.19298 | E13: =VLOOKUP(B13,'China Index ROIC'!$B:$D,2,FALSE) -> 5.445 | F13: =VLOOKUP(B13,'China Index ROIC'!$B:$D,3,FALSE) -> 1.5009 | G13: =VLOOKUP(B13,'China Index ROIC'!B:E,4,FALSE) -> 医药生物-医疗器械-体外诊断 | H13: 医疗 | I13: =CONCATENATE("https://gushitong.baidu.com/stock/ab-", B13) -> https://gushitong.baidu.com/stock/ab-300832
A14: 安图生物 | B14: 603658 | C14: =VLOOKUP(B14,当前走势!B:F,3,) -> 38.19 | D14: =VLOOKUP(B14,当前走势!$B:$F,5,FALSE)/100000000 -> 221.88823 | E14: =VLOOKUP(B14,'China Index ROIC'!$B:$D,2,FALSE) -> 3.51 | F14: =VLOOKUP(B14,'China Index ROIC'!$B:$D,3,FALSE) -> 1.7386 | G14: =VLOOKUP(B14,'China Index ROIC'!B:E,4,FALSE) -> 医药生物-医疗器械-体外诊断 | H14: 医疗 | I14: =CONCATENATE("https://gushitong.baidu.com/stock/ab-", B14) -> https://gushitong.baidu.com/stock/ab-603658
... A119: 华熙生物 | B119: 688363 | C119: =VLOOKUP(B119,当前走势!B:F,3,) -> 44.97 | D119: =VLOOKUP(B119,当前走势!$B:$F,5,FALSE)/100000000 -> 89.120755 | E119: =VLOOKUP(B119,'China Index ROIC'!$B:$D,2,FALSE) -> 3.4 | F119: =VLOOKUP(B119,'China Index ROIC'!$B:$D,3,FALSE) -> 1.0684 | G119: =VLOOKUP(B119,'China Index ROIC'!B:E,4,FALSE) -> 美容护理-美容护理-医疗美容 | H119: 可选消费 | I119: =CONCATENATE("https://gushitong.baidu.com/stock/ab-", B119) -> https://gushitong.baidu.com/stock/ab-688363

Sheet MSCI最终筛选标的 (2)
A1: 证券简称 | B1: 证券代码 | C1: 价格[0918] | D1: 流通市值[0918] | E1: ROIC中位数 | F1: ROIC方差 | G1: 行业 | H1: 分类 | I1: 走势详情
A2: 贵州茅台 | B2: 600519 | C2: 1266.9 | D2: 15914.77 | E2: 7.6 | F2: 1.3797 | G2: 食品饮料-白酒-白酒Ⅲ | H2: 可选消费 | I2: =CONCATENATE("https://gushitong.baidu.com/stock/ab-", B2) -> https://gushitong.baidu.com/stock/ab-600519
A3: 亿联网络 | B3: 300628 | C3: 34.98 | D3: 252.92761 | E3: 7.29 | F3: 1.8425 | G3: 通信-通信设备-通信终端及配件 | H3: 信息技术 | I3: =CONCATENATE("https://gushitong.baidu.com/stock/ab-", B3) -> https://gushitong.baidu.com/stock/ab-300628
A4: 泸州老窖 | B4: 000568 | C4: 100.02 | D4: 1467.4343 | E4: 6.96 | F4: 1.6021 | G4: 食品饮料-白酒-白酒Ⅲ | H4: 可选消费 | I4: =CONCATENATE("https://gushitong.baidu.com/stock/ab-", B4) -> https://gushitong.baidu.com/stock/ab-000568
A5: 法拉电子 | B5: 600563 | C5: 84.37 | D5: 189.8325 | E5: 5.92 | F5: 1.2579 | G5: 电子-元件-被动元件 | H5: 信息技术 | I5: =CONCATENATE("https://gushitong.baidu.com/stock/ab-", B5) -> https://gushitong.baidu.com/stock/ab-600563
A6: 片仔癀 | B6: 600436 | C6: 193.5 | D6: 1167.4188 | E6: 5.86 | F6: 2.0427 | G6: 医药生物-中药-中药Ⅲ | H6: 医疗 | I6: =CONCATENATE("https://gushitong.baidu.com/stock/ab-", B6) -> https://gushitong.baidu.com/stock/ab-600436
A7: 口子窖 | B7: 603589 | C7: 34.8 | D7: 208.14558 | E7: 5.55 | F7: 1.5514 | G7: 食品饮料-白酒-白酒Ⅲ | H7: 可选消费 | I7: =CONCATENATE("https://gushitong.baidu.com/stock/ab-", B7) -> https://gushitong.baidu.com/stock/ab-603589
A8: 新产业 | B8: 300832 | C8: 69.86 | D8: 475.19298 | E8: 5.445 | F8: 1.5009 | G8: 医药生物-医疗器械-体外诊断 | H8: 医疗 | I8: =CONCATENATE("https://gushitong.baidu.com/stock/ab-", B8) -> https://gushitong.baidu.com/stock/ab-300832
A9: 宝信软件 | B9: 600845 | C9: 29.37 | D9: 622.983 | E9: 5.25 | F9: 0.6881 | G9: 计算机-IT服务-IT服务Ⅲ | H9: 信息技术 | I9: =CONCATENATE("https://gushitong.baidu.com/stock/ab-", B9) -> https://gushitong.baidu.com/stock/ab-600845
A10: 晨光股份 | B10: 603899 | C10: 25.28 | D10: 233.54382 | E10: 5.24 | F10: 2.1007 | G10: 轻工制造-家居用品-文娱用品 | H10: 必选消费 | I10: =CONCATENATE("https://gushitong.baidu.com/stock/ab-", B10) -> https://gushitong.baidu.com/stock/ab-603899
A11: 珀莱雅 | B11: 603605 | C11: 85.94 | D11: 339.29143 | E11: 5.03 | F11: 2.235 | G11: 美容护理-美容护理-化妆品 | H11: 可选消费 | I11: =CONCATENATE("https://gushitong.baidu.com/stock/ab-", B11) -> https://gushitong.baidu.com/stock/ab-603605
A12: 汇川技术 | B12: 300124 | C12: 43.86 | D12: 994.35176 | E12: 4.96 | F12: 1.6424 | G12: 机械设备-自动化设备-工控设备 | H12: 信息技术 | I12: =CONCATENATE("https://gushitong.baidu.com/stock/ab-", B12) -> https://gushitong.baidu.com/stock/ab-300124
A13: 济川药业 | B13: 600566 | C13: 24.46 | D13: 223.992 | E13: 4.86 | F13: 0.855 | G13: 医药生物-中药-中药Ⅲ | H13: 医疗 | I13: =CONCATENATE("https://gushitong.baidu.com/stock/ab-", B13) -> https://gushitong.baidu.com/stock/ab-600566
... A119: 时代电气 | B119: 688187 | C119: 43.25 | D119: 120.80668 | E119: 1.99 | F119: 0.634 | G119: 机械设备-轨交设备-轨交设备Ⅲ | H119: 公共事业 | I119: =CONCATENATE("https://gushitong.baidu.com/stock/ab-", B119) -> https://gushitong.baidu.com/stock/ab-688187

Sheet 5+5
A1: 证券简称 | B1: 证券代码 | C1: 价格[0918] | D1: 流通市值[0918] | E1: ROIC中位数 | F1: ROIC方差 | G1: 行业 | H1: 分类 | I1: 走势详情
A2: 三花智控 | B2: 002050 | C2: 17.5 | D2: 642.32876 | E2: 3.28 | F2: 0.42 | G2: 家用电器-白色家电-家电零部件 | H2: 可选消费 | I2: =CONCATENATE("https://gushitong.baidu.com/stock/ab-", B2) -> https://gushitong.baidu.com/stock/ab-002050
A3: 宏发股份 | B3: 600885 | C3: 26.65 | D3: 277.87311 | E3: 3.3 | F3: 0.2927 | G3: 电力设备-电网设备-输变电设备 | H3: 能源/新能源 | I3: =CONCATENATE("https://gushitong.baidu.com/stock/ab-", B3) -> https://gushitong.baidu.com/stock/ab-600885
A4: 宝信软件 | B4: 600845 | C4: 29.37 | D4: 622.983 | E4: 5.25 | F4: 0.6881 | G4: 计算机-IT服务-IT服务Ⅲ | H4: 信息技术 | I4: =CONCATENATE("https://gushitong.baidu.com/stock/ab-", B4) -> https://gushitong.baidu.com/stock/ab-600845
A5: 国药股份 | B5: 600511 | C5: 27.4 | D5: 151.61692 | E5: 3.33 | F5: 0.4803 | G5: 医药生物-医药商业-医药流通 | H5: 医疗 | I5: =CONCATENATE("https://gushitong.baidu.com/stock/ab-", B5) -> https://gushitong.baidu.com/stock/ab-600511
A6: 济川药业 | B6: 600566 | C6: 24.46 | D6: 223.992 | E6: 4.86 | F6: 0.855 | G6: 医药生物-中药-中药Ⅲ | H6: 医疗 | I6: =CONCATENATE("https://gushitong.baidu.com/stock/ab-", B6) -> https://gushitong.baidu.com/stock/ab-600566
A7: 海澜之家 | B7: 600398 | C7: 5.24 | D7: 251.66516 | E7: 3.62 | F7: 0.8897 | G7: 纺织服饰-服装家纺-服装 | H7: 必选消费 | I7: =CONCATENATE("https://gushitong.baidu.com/stock/ab-", B7) -> https://gushitong.baidu.com/stock/ab-600398
A8: 豪迈科技 | B8: 002595 | C8: 43.2 | D8: 343.33848 | E8: 4.51 | F8: 0.7579 | G8: 机械设备-专用设备-其他专用设备 | H8: 工业 | I8: =CONCATENATE("https://gushitong.baidu.com/stock/ab-", B8) -> https://gushitong.baidu.com/stock/ab-002595
A9: 杰瑞股份 | B9: 002353 | C9: 27.07 | D9: 187.71295 | E9: 3.2 | F9: 0.9446 | G9: 机械设备-专用设备-能源及重型设备 | H9: 工业 | I9: =CONCATENATE("https://gushitong.baidu.com/stock/ab-", B9) -> https://gushitong.baidu.com/stock/ab-002353
A10: 杭叉集团 | B10: 603298 | C10: 18.55 | D10: 242.97014 | E10: 3.76 | F10: 1.0955 | G10: 机械设备-工程机械-工程机械Ⅲ | H10: 工业 | I10: =CONCATENATE("https://gushitong.baidu.com/stock/ab-", B10) -> https://gushitong.baidu.com/stock/ab-603298
A11: 中航光电 | B11: 002179 | C11: 37.06 | D11: 764.81109 | E11: 4.14 | F11: 1.1862 | G11: 国防军工-军工电子-军工电子Ⅲ | H11: 工业 | I11: =CONCATENATE("https://gushitong.baidu.com/stock/ab-", B11) -> https://gushitong.baidu.com/stock/ab-002179
A12: 伟明环保 | B12: 603568 | C12: 17.7 | D12: 300.61505 | E12: 3.65 | F12: 1.0215 | G12: 环保-环境治理-固废治理 | H12: 公共事业 | I12: =CONCATENATE("https://gushitong.baidu.com/stock/ab-", B12) -> https://gushitong.baidu.com/stock/ab-603568
A13: 海尔智家 | B13: 600690 | C13: 26.11 | D13: 1633.0502 | E13: 3.08 | F13: 0.7392 | G13: 家用电器-白色家电-冰洗 | H13: 可选消费 | I13: =CONCATENATE("https://gushitong.baidu.com/stock/ab-", B13) -> https://gushitong.baidu.com/stock/ab-600690
... A29: 光威复材 | B29: 300699 | C29: 26.92 | D29: 221.13247 | E29: 4.71 | F29: 1.2502 | G29: 国防军工-军工装备-航空装备 | H29: 原材料 | I29: =CONCATENATE("https://gushitong.baidu.com/stock/ab-", B29) -> https://gushitong.baidu.com/stock/ab-300699

Sheet 低价低市值+5+5
A1: 证券简称 | B1: 证券代码 | C1: 价格[0918] | D1: 流通市值[0918] | E1: ROIC中位数 | F1: ROIC方差 | G1: 行业 | H1: 分类 | I1: 走势详情
A2: 宏发股份 | B2: 600885 | C2: 26.65 | D2: 277.87311 | E2: 3.3 | F2: 0.2927 | G2: 电力设备-电网设备-输变电设备 | H2: 能源/新能源 | I2: https://gushitong.baidu.com/stock/ab-600885
A3: 山金国际 | B3: 000975 | C3: 16.18 | D3: 402.41137 | E3: 2.83 | F3: 0.3927 | G3: 有色金属-贵金属-贵金属Ⅲ | H3: 原材料 | I3: https://gushitong.baidu.com/stock/ab-000975
A4: 航天电器 | B4: 002025 | C4: 43.3 | D4: 195.95893 | E4: 3.07 | F4: 0.4332 | G4: 国防军工-军工电子-军工电子Ⅲ | H4: 工业 | I4: https://gushitong.baidu.com/stock/ab-002025
A5: 国药股份 | B5: 600511 | C5: 27.4 | D5: 151.61692 | E5: 3.33 | F5: 0.4803 | G5: 医药生物-医药商业-医药流通 | H5: 医疗 | I5: https://gushitong.baidu.com/stock/ab-600511
A6: 丽珠集团 | B6: 000513 | C6: 35.58 | D6: 213.33998 | E6: 2.99 | F6: 0.5408 | G6: 医药生物-化学制药-化学制剂 | H6: 医疗 | I6: https://gushitong.baidu.com/stock/ab-000513
A7: 豪迈科技 | B7: 002595 | C7: 43.2 | D7: 343.33848 | E7: 4.51 | F7: 0.7579 | G7: 机械设备-专用设备-其他专用设备 | H7: 工业 | I7: https://gushitong.baidu.com/stock/ab-002595
A8: 伯特利 | B8: 603596 | C8: 39.77 | D8: 240.72913 | E8: 3.7 | F8: 0.7678 | G8: 汽车-汽车零部件-底盘与发动机系统 | H8: 可选消费 | I8: https://gushitong.baidu.com/stock/ab-603596
A9: 济川药业 | B9: 600566 | C9: 24.46 | D9: 223.992 | E9: 4.86 | F9: 0.855 | G9: 医药生物-中药-中药Ⅲ | H9: 医疗 | I9: https://gushitong.baidu.com/stock/ab-600566
A10: 海澜之家 | B10: 600398 | C10: 5.24 | D10: 251.66516 | E10: 3.62 | F10: 0.8897 | G10: 纺织服饰-服装家纺-服装 | H10: 必选消费 | I10: https://gushitong.baidu.com/stock/ab-600398
A11: 中材国际 | B11: 600970 | C11: 8.8 | D11: 154.67443 | E11: 2.96 | F11: 0.9143 | G11: 建筑装饰-建筑装饰-专业工程 | H11: 原材料 | I11: https://gushitong.baidu.com/stock/ab-600970
A12: 杰瑞股份 | B12: 002353 | C12: 27.07 | D12: 187.71295 | E12: 3.2 | F12: 0.9446 | G12: 机械设备-专用设备-能源及重型设备 | H12: 工业 | I12: https://gushitong.baidu.com/stock/ab-002353
A13: 国瓷材料 | B13: 300285 | C13: 14.32 | D13: 115.12562 | E13: 3.28 | F13: 0.9496 | G13: 电子-电子化学品-电子化学品Ⅲ | H13: 原材料 | I13: https://gushitong.baidu.com/stock/ab-300285
... A17: 杭叉集团 | B17: 603298 | C17: 18.55 | D17: 242.97014 | E17: 3.76 | F17: 1.0955 | G17: 机械设备-工程机械-工程机械Ⅲ | H17: 工业 | I17: https://gushitong.baidu.com/stock/ab-603298

Sheet 深证+可选&信息技术
A1: 证券简称 | B1: 证券代码 | C1: 价格[0918] | D1: 流通市值[0918] | E1: ROIC中位数 | F1: ROIC方差 | G1: 行业 | H1: 分类 | I1: 走势详情
A2: 三花智控 | B2: 002050 | C2: 17.5 | D2: 642.32876 | E2: 3.28 | F2: 0.42 | G2: 家用电器-白色家电-家电零部件 | H2: 可选消费 | I2: https://gushitong.baidu.com/stock/ab-002050
A3: 美的集团 | B3: 000333 | C3: 65.25 | D3: 4488.2656 | E3: 3.78 | F3: 0.9086 | G3: 家用电器-白色家电-空调 | H3: 可选消费 | I3: https://gushitong.baidu.com/stock/ab-000333
A4: 深南电路 | B4: 002916 | C4: 96.64 | D4: 493.64875 | E4: 3.11 | F4: 0.9547 | G4: 电子-元件-印制电路板 | H4: 信息技术 | I4: https://gushitong.baidu.com/stock/ab-002916
A5: 扬杰科技 | B5: 300373 | C5: 33.66 | D5: 182.48697 | E5: 3.19 | F5: 1.0974 | G5: 电子-半导体-分立器件 | H5: 信息技术 | I5: https://gushitong.baidu.com/stock/ab-300373
A6: 安克创新 | B6: 300866 | C6: 68.96 | D6: 204.39872 | E6: 4.36 | F6: 1.3292 | G6: 电子-消费电子-品牌消费电子 | H6: 信息技术 | I6: https://gushitong.baidu.com/stock/ab-300866
A7: 沪电股份 | B7: 002463 | C7: 33.42 | D7: 639.66444 | E7: 3.93 | F7: 1.4067 | G7: 电子-元件-印制电路板 | H7: 信息技术 | I7: https://gushitong.baidu.com/stock/ab-002463
A8: 泸州老窖 | B8: 000568 | C8: 100.02 | D8: 1467.4343 | E8: 6.96 | F8: 1.6021 | G8: 食品饮料-白酒-白酒Ⅲ | H8: 可选消费 | I8: https://gushitong.baidu.com/stock/ab-000568

Sheet List
A1: 信息技术
A2: 医疗
A3: 金融
A4: 公共事业
A5: 可选消费
A6: 工业
A7: 原材料
A8: 必选消费
A9: 能源/新能源
